ERROR:Stock Ticker:Exception: ('Connection aborted.', gaierror(11001, 'getaddrinfo failed'))
Traceback (most recent call last):
  File "C:\Python34\lib\site-packages\requests-2.7.0-py2.7.egg\requests\packages\urllib3\connectionpool.py", line 544, in urlopen
    body=body, headers=headers)
  File "C:\Python34\lib\site-packages\requests-2.7.0-py2.7.egg\requests\packages\urllib3\connectionpool.py", line 349, in _make_request
    conn.request(method, url, **httplib_request_kw)
  File "C:\Python34\Lib\http\client.py", line 1088, in request
    self._send_request(method, url, body, headers)
  File "C:\Python34\Lib\http\client.py", line 1126, in _send_request
    self.endheaders(body)
  File "C:\Python34\Lib\http\client.py", line 1084, in endheaders
    self._send_output(message_body)
  File "C:\Python34\Lib\http\client.py", line 922, in _send_output
    self.send(msg)
  File "C:\Python34\Lib\http\client.py", line 857, in send
    self.connect()
  File "C:\Python34\lib\site-packages\requests-2.7.0-py2.7.egg\requests\packages\urllib3\connection.py", line 155, in connect
    conn = self._new_conn()
  File "C:\Python34\lib\site-packages\requests-2.7.0-py2.7.egg\requests\packages\urllib3\connection.py", line 134, in _new_conn
    (self.host, self.port), self.timeout, **extra_kw)
  File "C:\Python34\lib\site-packages\requests-2.7.0-py2.7.egg\requests\packages\urllib3\util\connection.py", line 64, in create_connection
    for res in socket.getaddrinfo(host, port, 0, socket.SOCK_STREAM):
  File "C:\Python34\Lib\socket.py", line 533, in getaddrinfo
    for res in _socket.getaddrinfo(host, port, family, type, proto, flags):
socket.gaierror: [Errno 11001] getaddrinfo failed

During handling of the above exception, another exception occurred:

Traceback (most recent call last):
  File "C:\Python34\lib\site-packages\requests-2.7.0-py2.7.egg\requests\adapters.py", line 370, in send
    timeout=timeout
  File "C:\Python34\lib\site-packages\requests-2.7.0-py2.7.egg\requests\packages\urllib3\connectionpool.py", line 597, in urlopen
    _stacktrace=sys.exc_info()[2])
  File "C:\Python34\lib\site-packages\requests-2.7.0-py2.7.egg\requests\packages\urllib3\util\retry.py", line 245, in increment
    raise six.reraise(type(error), error, _stacktrace)
  File "C:\Python34\lib\site-packages\requests-2.7.0-py2.7.egg\requests\packages\urllib3\packages\six.py", line 309, in reraise
    raise value.with_traceback(tb)
  File "C:\Python34\lib\site-packages\requests-2.7.0-py2.7.egg\requests\packages\urllib3\connectionpool.py", line 544, in urlopen
    body=body, headers=headers)
  File "C:\Python34\lib\site-packages\requests-2.7.0-py2.7.egg\requests\packages\urllib3\connectionpool.py", line 349, in _make_request
    conn.request(method, url, **httplib_request_kw)
  File "C:\Python34\Lib\http\client.py", line 1088, in request
    self._send_request(method, url, body, headers)
  File "C:\Python34\Lib\http\client.py", line 1126, in _send_request
    self.endheaders(body)
  File "C:\Python34\Lib\http\client.py", line 1084, in endheaders
    self._send_output(message_body)
  File "C:\Python34\Lib\http\client.py", line 922, in _send_output
    self.send(msg)
  File "C:\Python34\Lib\http\client.py", line 857, in send
    self.connect()
  File "C:\Python34\lib\site-packages\requests-2.7.0-py2.7.egg\requests\packages\urllib3\connection.py", line 155, in connect
    conn = self._new_conn()
  File "C:\Python34\lib\site-packages\requests-2.7.0-py2.7.egg\requests\packages\urllib3\connection.py", line 134, in _new_conn
    (self.host, self.port), self.timeout, **extra_kw)
  File "C:\Python34\lib\site-packages\requests-2.7.0-py2.7.egg\requests\packages\urllib3\util\connection.py", line 64, in create_connection
    for res in socket.getaddrinfo(host, port, 0, socket.SOCK_STREAM):
  File "C:\Python34\Lib\socket.py", line 533, in getaddrinfo
    for res in _socket.getaddrinfo(host, port, family, type, proto, flags):
requests.packages.urllib3.exceptions.ProtocolError: ('Connection aborted.', gaierror(11001, 'getaddrinfo failed'))

During handling of the above exception, another exception occurred:

Traceback (most recent call last):
  File "C:\Users\E002592\Documents\Projects\python\Stock Ticker\StockTickerEngine\StockTickerEngine.py", line 29, in GetStockQuote
    response = requests.get(url)
  File "C:\Python34\lib\site-packages\requests-2.7.0-py2.7.egg\requests\api.py", line 69, in get
    return request('get', url, params=params, **kwargs)
  File "C:\Python34\lib\site-packages\requests-2.7.0-py2.7.egg\requests\api.py", line 50, in request
    response = session.request(method=method, url=url, **kwargs)
  File "C:\Python34\lib\site-packages\requests-2.7.0-py2.7.egg\requests\sessions.py", line 470, in request
    resp = self.send(prep, **send_kwargs)
  File "C:\Python34\lib\site-packages\requests-2.7.0-py2.7.egg\requests\sessions.py", line 578, in send
    r = adapter.send(request, **kwargs)
  File "C:\Python34\lib\site-packages\requests-2.7.0-py2.7.egg\requests\adapters.py", line 412, in send
    raise ConnectionError(err, request=request)
requests.exceptions.ConnectionError: ('Connection aborted.', gaierror(11001, 'getaddrinfo failed'))

During handling of the above exception, another exception occurred:

Traceback (most recent call last):
  File "C:\Users\E002592\Documents\Projects\python\Stock Ticker\StockTickerManager.py", line 54, in Process
    self.ProcessQuoteByTicker(ticker)
  File "C:\Users\E002592\Documents\Projects\python\Stock Ticker\StockTickerManager.py", line 38, in ProcessQuoteByTicker
    quote = self._tickerHandler.GetStockQuote(ticker)
  File "C:\Users\E002592\Documents\Projects\python\Stock Ticker\StockTickerHandler.py", line 21, in GetStockQuote
    response = self.__stockTickerEngine.GetStockQuote(tickerSymbol)
  File "C:\Users\E002592\Documents\Projects\python\Stock Ticker\StockTickerEngine\StockTickerEngine.py", line 33, in GetStockQuote
    raise requests.exceptions.RequestException(str(requestErr))
requests.exceptions.RequestException: ('Connection aborted.', gaierror(11001, 'getaddrinfo failed'))
